<?xml version="1.0" ?>
<!-- =================================================================================== -->
<!-- |    This document was autogenerated by xacro from gp8.urdf.xacro                 | -->
<!-- |    EDITING THIS FILE BY HAND IS NOT RECOMMENDED                                 | -->
<!-- =================================================================================== -->
<robot name="gp8" xmlns:xacro="http://www.ros.org/wiki/xacro">
  <!-- Properties -->
  <material name="yaskawa_blue">
    <color rgba="0.12941 0.14902 0.74902 1"/>
  </material>
  <!-- link list -->
  <link name="gp8_1_base_link">
    <visual>
      <geometry>
        <mesh filename="package://beg_tut/meshes/motoman_gp8/visual/gp8_base_link.stl"/>
      </geometry>
      <material name="yaskawa_blue"/>
    </visual>
    <collision>
      <geometry>
        <mesh filename="package://beg_tut/meshes/motoman_gp8/collision/gp8_base_link.stl"/>
      </geometry>
    </collision>
  </link>
  <link name="gp8_1_link_1_s">
    <visual>
      <geometry>
        <mesh filename="package://beg_tut/meshes/motoman_gp8/visual/gp8_link_1_s.stl"/>
      </geometry>
      <material name="yaskawa_blue"/>
    </visual>
    <collision>
      <geometry>
        <mesh filename="package://beg_tut/meshes/motoman_gp8/collision/gp8_link_1_s.stl"/>
      </geometry>
    </collision>
  </link>
  <link name="gp8_1_link_2_l">
    <visual>
      <geometry>
        <mesh filename="package://beg_tut/meshes/motoman_gp8/visual/gp8_link_2_l.stl"/>
      </geometry>
      <material name="yaskawa_blue"/>
    </visual>
    <collision>
      <geometry>
        <mesh filename="package://beg_tut/meshes/motoman_gp8/collision/gp8_link_2_l.stl"/>
      </geometry>
    </collision>
  </link>
  <link name="gp8_1_link_3_u">
    <visual>
      <geometry>
        <mesh filename="package://beg_tut/meshes/motoman_gp8/visual/gp8_link_3_u.stl"/>
      </geometry>
      <material name="yaskawa_blue"/>
    </visual>
    <collision>
      <geometry>
        <mesh filename="package://beg_tut/meshes/motoman_gp8/collision/gp8_link_3_u.stl"/>
      </geometry>
    </collision>
  </link>
  <link name="gp8_1_link_4_r">
    <visual>
      <geometry>
        <mesh filename="package://beg_tut/meshes/motoman_gp8/visual/gp8_link_4_r.stl"/>
      </geometry>
      <material name="yaskawa_blue"/>
    </visual>
    <collision>
      <geometry>
        <mesh filename="package://beg_tut/meshes/motoman_gp8/collision/gp8_link_4_r.stl"/>
      </geometry>
    </collision>
  </link>
  <link name="gp8_1_link_5_b">
    <visual>
      <geometry>
        <mesh filename="package://beg_tut/meshes/motoman_gp8/visual/gp8_link_5_b.stl"/>
      </geometry>
      <material name="yaskawa_blue"/>
    </visual>
    <collision>
      <geometry>
        <mesh filename="package://beg_tut/meshes/motoman_gp8/collision/gp8_link_5_b.stl"/>
      </geometry>
    </collision>
  </link>
  <link name="gp8_1_link_6_t">
    <visual>
      <geometry>
        <mesh filename="package://beg_tut/meshes/motoman_gp8/visual/gp8_link_6_t.stl"/>
      </geometry>
      <material name="yaskawa_blue"/>
    </visual>
    <collision>
      <geometry>
        <mesh filename="package://beg_tut/meshes/motoman_gp8/collision/gp8_link_6_t.stl"/>
      </geometry>
    </collision>
  </link>
  <link name="gp8_1_tool0"/>
  <!-- end of link list -->
  <!-- joint list -->
  <joint name="gp8_1_joint_1" type="revolute">
    <parent link="gp8_1_base_link"/>
    <child link="gp8_1_link_1_s"/>
    <origin rpy="0 0 0" xyz="0 0 0.330"/>
    <axis xyz="0 0 1"/>
    <limit effort="150.92" lower="-2.9670" upper="2.9670" velocity="7.9412"/>
  </joint>
  <joint name="gp8_1_joint_2" type="revolute">
    <parent link="gp8_1_link_1_s"/>
    <child link="gp8_1_link_2_l"/>
    <origin rpy="0 0 0" xyz="0.040 0 0"/>
    <axis xyz="0 1 0"/>
    <limit effort="176.4" lower="-1.1344" upper="2.5307" velocity="6.7495"/>
  </joint>
  <joint name="gp8_1_joint_3" type="revolute">
    <parent link="gp8_1_link_2_l"/>
    <child link="gp8_1_link_3_u"/>
    <origin rpy="0 0 0" xyz="0 0 0.345"/>
    <axis xyz="0 -1 0"/>
    <limit effort="107.56" lower="-1.2217" upper="3.3161" velocity="9.0757"/>
  </joint>
  <joint name="gp8_1_joint_4" type="revolute">
    <parent link="gp8_1_link_3_u"/>
    <child link="gp8_1_link_4_r"/>
    <origin rpy="0 0 0" xyz="0.340 0 0.040"/>
    <axis xyz="-1 0 0"/>
    <limit effort="55.86" lower="-3.3161" upper="3.3161" velocity="9.5993"/>
  </joint>
  <joint name="gp8_1_joint_5" type="revolute">
    <parent link="gp8_1_link_4_r"/>
    <child link="gp8_1_link_5_b"/>
    <origin rpy="0 0 0" xyz="0 0 0"/>
    <axis xyz="0 -1 0"/>
    <limit effort="32.68" lower="-2.3561" upper="2.3561" velocity="9.5993"/>
  </joint>
  <joint name="gp8_1_joint_6" type="revolute">
    <parent link="gp8_1_link_5_b"/>
    <child link="gp8_1_link_6_t"/>
    <origin rpy="0 0 0" xyz="0 0 0"/>
    <axis xyz="-1 0 0"/>
    <limit effort="22.54" lower="-6.2944" upper="6.2944" velocity="17.4845"/>
  </joint>
  <joint name="gp8_1_joint_6_t-tool0" type="fixed">
    <origin rpy="3.1415926 -1.570796 0" xyz="0.080 0 0"/>
    <parent link="gp8_1_link_6_t"/>
    <child link="gp8_1_tool0"/>
  </joint>
  <!-- end of joint list -->
  <!-- ROS base_link to Robot Manufacturer World Coordinates transform -->
  <link name="world"/>
  <joint name="gp8_1_base_link-base" type="fixed">
    <origin rpy="0 0 0" xyz="0 0 0"/>
    <parent link="world"/>
    <child link="gp8_1_base_link"/>
  </joint>
</robot>

